2024-04-18T20:45:54 {"cpu": 0.32373046875, "cpu_total": 2, "cpu_usage": 0.161865234375, "memory": 4032.0, "memory_total": 8883.0, "memory_usage": 0.45390070921985815, "pipeline_run_id": 3, "pipeline_schedule_id": 4, "pipeline_uuid": "playful_grimoire", "hostname": "7902c592f721", "level": "INFO", "message": "Pipeline playful_grimoire for run 3 in schedule 4 is alive.", "timestamp": 1713473154.376981, "uuid": "5bcc865fb8e6426aa63d373b98d47bf4"}
2024-04-18T20:45:54 {"block_run_id": 21, "block_uuid": "metmuseumobjects", "pipeline_run_id": 3, "pipeline_schedule_id": 4, "pipeline_uuid": "playful_grimoire", "hostname": "7902c592f721", "level": "INFO", "message": "Execute PipelineRun 3, BlockRun 21: pipeline playful_grimoire block metmuseumobjects", "timestamp": 1713473154.615488, "uuid": "8b6dc031fb684b8f9c496880cd281993"}
2024-04-18T20:45:54 {"cpu": 0.32373046875, "cpu_total": 2, "cpu_usage": 0.161865234375, "memory": 4064.0, "memory_total": 8883.0, "memory_usage": 0.45750309580096815, "pipeline_run_id": 3, "pipeline_schedule_id": 4, "pipeline_uuid": "playful_grimoire", "hostname": "7902c592f721", "level": "INFO", "message": "Pipeline playful_grimoire for run 3 in schedule 4 is alive.", "timestamp": 1713473154.619939, "uuid": "16a7bff37c9349d999d9e6edeefa4467"}
2024-04-18T20:45:55 {"block_run_id": 22, "block_uuid": "met_directors", "pipeline_run_id": 3, "pipeline_schedule_id": 4, "pipeline_uuid": "playful_grimoire", "hostname": "7902c592f721", "level": "INFO", "message": "Execute PipelineRun 3, BlockRun 22: pipeline playful_grimoire block met_directors", "timestamp": 1713473155.713978, "uuid": "d6e95c3dba234afa949b7244b5faf3d2"}
2024-04-18T20:45:58 {"block_run_id": 22, "block_uuid": "met_directors", "pipeline_run_id": 3, "pipeline_schedule_id": 4, "pipeline_uuid": "playful_grimoire", "hostname": "7902c592f721", "level": "INFO", "message": "BlockRun 22 (block_uuid: met_directors) completes.", "timestamp": 1713473158.166644, "uuid": "53e2eacac6de44a691bd1ab5a17ff12e"}
2024-04-18T20:46:03 {"cpu": 0.3369140625, "cpu_total": 2, "cpu_usage": 0.16845703125, "memory": 4741.0, "memory_total": 8883.0, "memory_usage": 0.5337160869075762, "pipeline_run_id": 3, "pipeline_schedule_id": 4, "pipeline_uuid": "playful_grimoire", "hostname": "7902c592f721", "level": "INFO", "message": "Pipeline playful_grimoire for run 3 in schedule 4 is alive.", "timestamp": 1713473163.860192, "uuid": "57861e4b0b044d7fbd798cbf69f98fb3"}
2024-04-18T20:46:04 {"block_run_id": 24, "block_uuid": "prep_directors", "pipeline_run_id": 3, "pipeline_schedule_id": 4, "pipeline_uuid": "playful_grimoire", "hostname": "7902c592f721", "level": "INFO", "message": "Execute PipelineRun 3, BlockRun 24: pipeline playful_grimoire block prep_directors", "timestamp": 1713473164.857812, "uuid": "84c3a2d39360492bb3f2897381537172"}
2024-04-18T20:46:06 {"block_run_id": 24, "block_uuid": "prep_directors", "pipeline_run_id": 3, "pipeline_schedule_id": 4, "pipeline_uuid": "playful_grimoire", "hostname": "7902c592f721", "level": "INFO", "message": "BlockRun 24 (block_uuid: prep_directors) completes.", "timestamp": 1713473166.830541, "uuid": "9efbb4ff9c914a379958172b41c40175"}
2024-04-18T20:46:14 {"cpu": 0.3388671875, "cpu_total": 2, "cpu_usage": 0.16943359375, "memory": 4581.0, "memory_total": 8883.0, "memory_usage": 0.5157041540020263, "pipeline_run_id": 3, "pipeline_schedule_id": 4, "pipeline_uuid": "playful_grimoire", "hostname": "7902c592f721", "level": "INFO", "message": "Pipeline playful_grimoire for run 3 in schedule 4 is alive.", "timestamp": 1713473174.159453, "uuid": "042d469af3a44ccd8f13a49748217530"}
2024-04-18T20:46:14 {"block_run_id": 28, "block_uuid": "directors_table", "pipeline_run_id": 3, "pipeline_schedule_id": 4, "pipeline_uuid": "playful_grimoire", "hostname": "7902c592f721", "level": "INFO", "message": "Execute PipelineRun 3, BlockRun 28: pipeline playful_grimoire block directors_table", "timestamp": 1713473174.92485, "uuid": "e5a2c5b25e5b4a8d99e275929b524173"}
2024-04-18T20:46:14 {"block_run_id": 26, "block_uuid": "gcs_directors", "pipeline_run_id": 3, "pipeline_schedule_id": 4, "pipeline_uuid": "playful_grimoire", "hostname": "7902c592f721", "level": "INFO", "message": "Execute PipelineRun 3, BlockRun 26: pipeline playful_grimoire block gcs_directors", "timestamp": 1713473174.934025, "uuid": "1a2405b9e85841728c96c0c30e916c98"}
2024-04-18T20:46:17 {"block_run_id": 26, "block_uuid": "gcs_directors", "pipeline_run_id": 3, "pipeline_schedule_id": 4, "pipeline_uuid": "playful_grimoire", "hostname": "7902c592f721", "level": "INFO", "message": "BlockRun 26 (block_uuid: gcs_directors) completes.", "timestamp": 1713473177.81646, "uuid": "91e7ddabb5a74916bd9f511a21780139"}
2024-04-18T20:46:19 {"block_run_id": 28, "block_uuid": "directors_table", "pipeline_run_id": 3, "pipeline_schedule_id": 4, "pipeline_uuid": "playful_grimoire", "hostname": "7902c592f721", "level": "EXCEPTION", "message": "BlockRun 28 (block_uuid: directors_table) failed.", "timestamp": 1713473179.233012, "uuid": "9f4cea25c0804582bcd79c0ff6952823", "error": ["Traceback (most recent call last):\n  File \"/usr/local/lib/python3.10/site-packages/mage_ai/data_preparation/executors/block_executor.py\", line 613, in execute\n    result = __execute_with_retry()\n  File \"/usr/local/lib/python3.10/site-packages/mage_ai/shared/retry.py\", line 54, in retry_func\n    raise e\n  File \"/usr/local/lib/python3.10/site-packages/mage_ai/shared/retry.py\", line 38, in retry_func\n    return func(*args, **kwargs)\n  File \"/usr/local/lib/python3.10/site-packages/mage_ai/data_preparation/executors/block_executor.py\", line 588, in __execute_with_retry\n    return self._execute(\n  File \"/usr/local/lib/python3.10/site-packages/mage_ai/data_preparation/executors/block_executor.py\", line 1077, in _execute\n    result = self.block.execute_sync(\n  File \"/usr/local/lib/python3.10/site-packages/mage_ai/data_preparation/models/block/__init__.py\", line 1315, in execute_sync\n    raise err\n  File \"/usr/local/lib/python3.10/site-packages/mage_ai/data_preparation/models/block/__init__.py\", line 1224, in execute_sync\n    output = self.execute_block(\n  File \"/usr/local/lib/python3.10/site-packages/mage_ai/data_preparation/models/block/__init__.py\", line 1530, in execute_block\n    outputs = self._execute_block(\n  File \"/usr/local/lib/python3.10/site-packages/mage_ai/data_preparation/models/block/r/__init__.py\", line 158, in _execute_block\n    outputs = execute_r_code(\n  File \"/usr/local/lib/python3.10/site-packages/mage_ai/data_preparation/models/block/r/__init__.py\", line 57, in execute_r_code\n    __execute_r_code(file_path)\n  File \"/usr/local/lib/python3.10/site-packages/mage_ai/data_preparation/models/block/r/__init__.py\", line 139, in __execute_r_code\n    subprocess.run(\n  File \"/usr/local/lib/python3.10/subprocess.py\", line 526, in run\n    raise CalledProcessError(retcode, process.args,\nsubprocess.CalledProcessError: Command '['Rscript', '--vanilla', '/tmp/fe990d9e-3db5-4d74-96a2-3b20f5a78048.r']' returned non-zero exit status 1.\n"], "error_stack": [["  File \"/usr/local/bin/mage\", line 8, in <module>\n    sys.exit(app())\n", "  File \"/usr/local/lib/python3.10/site-packages/typer/main.py\", line 311, in __call__\n    return get_command(self)(*args, **kwargs)\n", "  File \"/usr/local/lib/python3.10/site-packages/click/core.py\", line 1130, in __call__\n    return self.main(*args, **kwargs)\n", "  File \"/usr/local/lib/python3.10/site-packages/typer/core.py\", line 778, in main\n    return _main(\n", "  File \"/usr/local/lib/python3.10/site-packages/typer/core.py\", line 216, in _main\n    rv = self.invoke(ctx)\n", "  File \"/usr/local/lib/python3.10/site-packages/click/core.py\", line 1657, in invoke\n    return _process_result(sub_ctx.command.invoke(sub_ctx))\n", "  File \"/usr/local/lib/python3.10/site-packages/click/core.py\", line 1404, in invoke\n    return ctx.invoke(self.callback, **ctx.params)\n", "  File \"/usr/local/lib/python3.10/site-packages/click/core.py\", line 760, in invoke\n    return __callback(*args, **kwargs)\n", "  File \"/usr/local/lib/python3.10/site-packages/typer/main.py\", line 683, in wrapper\n    return callback(**use_params)  # type: ignore\n", "  File \"/usr/local/lib/python3.10/site-packages/mage_ai/cli/main.py\", line 163, in start\n    start_server(\n", "  File \"/usr/local/lib/python3.10/site-packages/mage_ai/server/server.py\", line 659, in start_server\n    scheduler_manager.start_scheduler()\n", "  File \"/usr/local/lib/python3.10/site-packages/mage_ai/server/scheduler_manager.py\", line 87, in start_scheduler\n    proc.start()\n", "  File \"/usr/local/lib/python3.10/multiprocessing/process.py\", line 121, in start\n    self._popen = self._Popen(self)\n", "  File \"/usr/local/lib/python3.10/multiprocessing/context.py\", line 224, in _Popen\n    return _default_context.get_context().Process._Popen(process_obj)\n", "  File \"/usr/local/lib/python3.10/multiprocessing/context.py\", line 281, in _Popen\n    return Popen(process_obj)\n", "  File \"/usr/local/lib/python3.10/multiprocessing/popen_fork.py\", line 19, in __init__\n    self._launch(process_obj)\n", "  File \"/usr/local/lib/python3.10/multiprocessing/popen_fork.py\", line 71, in _launch\n    code = process_obj._bootstrap(parent_sentinel=child_r)\n", "  File \"/usr/local/lib/python3.10/multiprocessing/process.py\", line 314, in _bootstrap\n    self.run()\n", "  File \"/usr/local/lib/python3.10/multiprocessing/process.py\", line 108, in run\n    self._target(*self._args, **self._kwargs)\n", "  File \"/usr/local/lib/python3.10/site-packages/mage_ai/orchestration/db/process.py\", line 15, in start_session_and_run\n    results = target(*args)\n", "  File \"/usr/local/lib/python3.10/site-packages/mage_ai/server/scheduler_manager.py\", line 50, in run_scheduler\n    LoopTimeTrigger().start()\n", "  File \"/usr/local/lib/python3.10/site-packages/mage_ai/orchestration/triggers/loop_time_trigger.py\", line 14, in start\n    self.run()\n", "  File \"/usr/local/lib/python3.10/site-packages/mage_ai/orchestration/triggers/time_trigger.py\", line 11, in run\n    schedule_all()\n", "  File \"/usr/local/lib/python3.10/site-packages/mage_ai/orchestration/pipeline_scheduler_original.py\", line 1582, in schedule_all\n    PipelineScheduler(r).start()\n", "  File \"/usr/local/lib/python3.10/site-packages/mage_ai/orchestration/db/__init__.py\", line 149, in func_with_rollback\n    return func(*args, **kwargs)\n", "  File \"/usr/local/lib/python3.10/site-packages/mage_ai/orchestration/pipeline_scheduler_original.py\", line 182, in start\n    self.schedule()\n", "  File \"/usr/local/lib/python3.10/site-packages/mage_ai/orchestration/db/__init__.py\", line 149, in func_with_rollback\n    return func(*args, **kwargs)\n", "  File \"/usr/local/lib/python3.10/site-packages/mage_ai/orchestration/pipeline_scheduler_original.py\", line 315, in schedule\n    self.__schedule_blocks(block_runs)\n", "  File \"/usr/local/lib/python3.10/site-packages/mage_ai/orchestration/pipeline_scheduler_original.py\", line 591, in __schedule_blocks\n    job_manager.add_job(\n", "  File \"/usr/local/lib/python3.10/site-packages/mage_ai/orchestration/job_manager.py\", line 27, in add_job\n    self.queue.enqueue(job_id, target, *args, **kwargs)\n", "  File \"/usr/local/lib/python3.10/site-packages/mage_ai/orchestration/queue/process_queue.py\", line 108, in enqueue\n    self.start_worker_pool()\n", "  File \"/usr/local/lib/python3.10/site-packages/mage_ai/orchestration/queue/process_queue.py\", line 183, in start_worker_pool\n    self.worker_pool_proc.start()\n", "  File \"/usr/local/lib/python3.10/multiprocessing/process.py\", line 121, in start\n    self._popen = self._Popen(self)\n", "  File \"/usr/local/lib/python3.10/multiprocessing/context.py\", line 224, in _Popen\n    return _default_context.get_context().Process._Popen(process_obj)\n", "  File \"/usr/local/lib/python3.10/multiprocessing/context.py\", line 281, in _Popen\n    return Popen(process_obj)\n", "  File \"/usr/local/lib/python3.10/multiprocessing/popen_fork.py\", line 19, in __init__\n    self._launch(process_obj)\n", "  File \"/usr/local/lib/python3.10/multiprocessing/popen_fork.py\", line 71, in _launch\n    code = process_obj._bootstrap(parent_sentinel=child_r)\n", "  File \"/usr/local/lib/python3.10/multiprocessing/process.py\", line 314, in _bootstrap\n    self.run()\n", "  File \"/usr/local/lib/python3.10/multiprocessing/process.py\", line 108, in run\n    self._target(*self._args, **self._kwargs)\n", "  File \"/usr/local/lib/python3.10/site-packages/mage_ai/orchestration/queue/process_queue.py\", line 288, in poll_job_and_execute\n    worker.start()\n", "  File \"/usr/local/lib/python3.10/multiprocessing/process.py\", line 121, in start\n    self._popen = self._Popen(self)\n", "  File \"/usr/local/lib/python3.10/multiprocessing/context.py\", line 224, in _Popen\n    return _default_context.get_context().Process._Popen(process_obj)\n", "  File \"/usr/local/lib/python3.10/multiprocessing/context.py\", line 281, in _Popen\n    return Popen(process_obj)\n", "  File \"/usr/local/lib/python3.10/multiprocessing/popen_fork.py\", line 19, in __init__\n    self._launch(process_obj)\n", "  File \"/usr/local/lib/python3.10/multiprocessing/popen_fork.py\", line 71, in _launch\n    code = process_obj._bootstrap(parent_sentinel=child_r)\n", "  File \"/usr/local/lib/python3.10/multiprocessing/process.py\", line 314, in _bootstrap\n    self.run()\n", "  File \"/usr/local/lib/python3.10/site-packages/newrelic/api/background_task.py\", line 117, in wrapper\n    return wrapped(*args, **kwargs)\n", "  File \"/usr/local/lib/python3.10/site-packages/mage_ai/orchestration/queue/process_queue.py\", line 253, in run\n    start_session_and_run(args[1], *args[2], **args[3])\n", "  File \"/usr/local/lib/python3.10/site-packages/mage_ai/orchestration/db/process.py\", line 15, in start_session_and_run\n    results = target(*args)\n", "  File \"/usr/local/lib/python3.10/site-packages/mage_ai/orchestration/pipeline_scheduler_original.py\", line 1135, in run_block\n    return ExecutorFactory.get_block_executor(\n", "  File \"/usr/local/lib/python3.10/site-packages/mage_ai/data_preparation/executors/block_executor.py\", line 641, in execute\n    on_failure(\n", "  File \"/usr/local/lib/python3.10/site-packages/mage_ai/orchestration/db/__init__.py\", line 149, in func_with_rollback\n    return func(*args, **kwargs)\n", "  File \"/usr/local/lib/python3.10/site-packages/mage_ai/orchestration/pipeline_scheduler_original.py\", line 422, in on_block_failure\n    self.logger.exception(\n", "  File \"/usr/local/lib/python3.10/site-packages/mage_ai/data_preparation/logging/logger.py\", line 30, in exception\n    self.__send_message('exception', message, **kwargs)\n", "  File \"/usr/local/lib/python3.10/site-packages/mage_ai/data_preparation/logging/logger.py\", line 59, in __send_message\n    data['error_stack'] = traceback.format_stack(),\n"]], "error_stacktrace": ["Command '['Rscript', '--vanilla', '/tmp/fe990d9e-3db5-4d74-96a2-3b20f5a78048.r']' returned non-zero exit status 1."]}
Traceback (most recent call last):
  File "/usr/local/lib/python3.10/site-packages/mage_ai/data_preparation/executors/block_executor.py", line 613, in execute
    result = __execute_with_retry()
  File "/usr/local/lib/python3.10/site-packages/mage_ai/shared/retry.py", line 54, in retry_func
    raise e
  File "/usr/local/lib/python3.10/site-packages/mage_ai/shared/retry.py", line 38, in retry_func
    return func(*args, **kwargs)
  File "/usr/local/lib/python3.10/site-packages/mage_ai/data_preparation/executors/block_executor.py", line 588, in __execute_with_retry
    return self._execute(
  File "/usr/local/lib/python3.10/site-packages/mage_ai/data_preparation/executors/block_executor.py", line 1077, in _execute
    result = self.block.execute_sync(
  File "/usr/local/lib/python3.10/site-packages/mage_ai/data_preparation/models/block/__init__.py", line 1315, in execute_sync
    raise err
  File "/usr/local/lib/python3.10/site-packages/mage_ai/data_preparation/models/block/__init__.py", line 1224, in execute_sync
    output = self.execute_block(
  File "/usr/local/lib/python3.10/site-packages/mage_ai/data_preparation/models/block/__init__.py", line 1530, in execute_block
    outputs = self._execute_block(
  File "/usr/local/lib/python3.10/site-packages/mage_ai/data_preparation/models/block/r/__init__.py", line 158, in _execute_block
    outputs = execute_r_code(
  File "/usr/local/lib/python3.10/site-packages/mage_ai/data_preparation/models/block/r/__init__.py", line 57, in execute_r_code
    __execute_r_code(file_path)
  File "/usr/local/lib/python3.10/site-packages/mage_ai/data_preparation/models/block/r/__init__.py", line 139, in __execute_r_code
    subprocess.run(
  File "/usr/local/lib/python3.10/subprocess.py", line 526, in run
    raise CalledProcessError(retcode, process.args,
subprocess.CalledProcessError: Command '['Rscript', '--vanilla', '/tmp/fe990d9e-3db5-4d74-96a2-3b20f5a78048.r']' returned non-zero exit status 1.
2024-04-18T20:46:24 {"cpu": 0.3408203125, "cpu_total": 2, "cpu_usage": 0.17041015625, "memory": 4598.0, "memory_total": 8883.0, "memory_usage": 0.5176179218732411, "pipeline_run_id": 3, "pipeline_schedule_id": 4, "pipeline_uuid": "playful_grimoire", "hostname": "7902c592f721", "level": "INFO", "message": "Pipeline playful_grimoire for run 3 in schedule 4 is alive.", "timestamp": 1713473184.580912, "uuid": "3c4fc6ffca7c4cb890da45aa04541686"}
2024-04-18T20:46:34 {"cpu": 0.3486328125, "cpu_total": 2, "cpu_usage": 0.17431640625, "memory": 4545.0, "memory_total": 8883.0, "memory_usage": 0.5116514690982776, "pipeline_run_id": 3, "pipeline_schedule_id": 4, "pipeline_uuid": "playful_grimoire", "hostname": "7902c592f721", "level": "INFO", "message": "Pipeline playful_grimoire for run 3 in schedule 4 is alive.", "timestamp": 1713473194.412779, "uuid": "27ef419d79c241e4afeafc1bff33c7ae"}
2024-04-18T20:46:34 {"block_run_id": 21, "block_uuid": "metmuseumobjects", "pipeline_run_id": 3, "pipeline_schedule_id": 4, "pipeline_uuid": "playful_grimoire", "hostname": "7902c592f721", "level": "INFO", "message": "Execute PipelineRun 3, BlockRun 21: pipeline playful_grimoire block metmuseumobjects", "timestamp": 1713473194.838128, "uuid": "d662e760221543558bf37b7eb52aa00a"}
2024-04-18T20:46:35 {"block_run_id": 28, "block_uuid": "directors_table", "pipeline_run_id": 3, "pipeline_schedule_id": 4, "pipeline_uuid": "playful_grimoire", "hostname": "7902c592f721", "level": "INFO", "message": "Execute PipelineRun 3, BlockRun 28: pipeline playful_grimoire block directors_table", "timestamp": 1713473195.911802, "uuid": "d0eab9cd9c8d426fad265abf73f4037f"}
2024-04-18T20:46:41 {"block_run_id": 28, "block_uuid": "directors_table", "pipeline_run_id": 3, "pipeline_schedule_id": 4, "pipeline_uuid": "playful_grimoire", "hostname": "7902c592f721", "level": "EXCEPTION", "message": "BlockRun 28 (block_uuid: directors_table) failed.", "timestamp": 1713473201.390193, "uuid": "cd2e3ff0203c46f685a1e20912454c5e", "error": ["Traceback (most recent call last):\n  File \"/usr/local/lib/python3.10/site-packages/mage_ai/data_preparation/executors/block_executor.py\", line 613, in execute\n    result = __execute_with_retry()\n  File \"/usr/local/lib/python3.10/site-packages/mage_ai/shared/retry.py\", line 54, in retry_func\n    raise e\n  File \"/usr/local/lib/python3.10/site-packages/mage_ai/shared/retry.py\", line 38, in retry_func\n    return func(*args, **kwargs)\n  File \"/usr/local/lib/python3.10/site-packages/mage_ai/data_preparation/executors/block_executor.py\", line 588, in __execute_with_retry\n    return self._execute(\n  File \"/usr/local/lib/python3.10/site-packages/mage_ai/data_preparation/executors/block_executor.py\", line 1077, in _execute\n    result = self.block.execute_sync(\n  File \"/usr/local/lib/python3.10/site-packages/mage_ai/data_preparation/models/block/__init__.py\", line 1315, in execute_sync\n    raise err\n  File \"/usr/local/lib/python3.10/site-packages/mage_ai/data_preparation/models/block/__init__.py\", line 1224, in execute_sync\n    output = self.execute_block(\n  File \"/usr/local/lib/python3.10/site-packages/mage_ai/data_preparation/models/block/__init__.py\", line 1530, in execute_block\n    outputs = self._execute_block(\n  File \"/usr/local/lib/python3.10/site-packages/mage_ai/data_preparation/models/block/r/__init__.py\", line 158, in _execute_block\n    outputs = execute_r_code(\n  File \"/usr/local/lib/python3.10/site-packages/mage_ai/data_preparation/models/block/r/__init__.py\", line 57, in execute_r_code\n    __execute_r_code(file_path)\n  File \"/usr/local/lib/python3.10/site-packages/mage_ai/data_preparation/models/block/r/__init__.py\", line 139, in __execute_r_code\n    subprocess.run(\n  File \"/usr/local/lib/python3.10/subprocess.py\", line 526, in run\n    raise CalledProcessError(retcode, process.args,\nsubprocess.CalledProcessError: Command '['Rscript', '--vanilla', '/tmp/f16f2f8f-daeb-4838-b29b-2799532c782d.r']' returned non-zero exit status 1.\n"], "error_stack": [["  File \"/usr/local/bin/mage\", line 8, in <module>\n    sys.exit(app())\n", "  File \"/usr/local/lib/python3.10/site-packages/typer/main.py\", line 311, in __call__\n    return get_command(self)(*args, **kwargs)\n", "  File \"/usr/local/lib/python3.10/site-packages/click/core.py\", line 1130, in __call__\n    return self.main(*args, **kwargs)\n", "  File \"/usr/local/lib/python3.10/site-packages/typer/core.py\", line 778, in main\n    return _main(\n", "  File \"/usr/local/lib/python3.10/site-packages/typer/core.py\", line 216, in _main\n    rv = self.invoke(ctx)\n", "  File \"/usr/local/lib/python3.10/site-packages/click/core.py\", line 1657, in invoke\n    return _process_result(sub_ctx.command.invoke(sub_ctx))\n", "  File \"/usr/local/lib/python3.10/site-packages/click/core.py\", line 1404, in invoke\n    return ctx.invoke(self.callback, **ctx.params)\n", "  File \"/usr/local/lib/python3.10/site-packages/click/core.py\", line 760, in invoke\n    return __callback(*args, **kwargs)\n", "  File \"/usr/local/lib/python3.10/site-packages/typer/main.py\", line 683, in wrapper\n    return callback(**use_params)  # type: ignore\n", "  File \"/usr/local/lib/python3.10/site-packages/mage_ai/cli/main.py\", line 163, in start\n    start_server(\n", "  File \"/usr/local/lib/python3.10/site-packages/mage_ai/server/server.py\", line 659, in start_server\n    scheduler_manager.start_scheduler()\n", "  File \"/usr/local/lib/python3.10/site-packages/mage_ai/server/scheduler_manager.py\", line 87, in start_scheduler\n    proc.start()\n", "  File \"/usr/local/lib/python3.10/multiprocessing/process.py\", line 121, in start\n    self._popen = self._Popen(self)\n", "  File \"/usr/local/lib/python3.10/multiprocessing/context.py\", line 224, in _Popen\n    return _default_context.get_context().Process._Popen(process_obj)\n", "  File \"/usr/local/lib/python3.10/multiprocessing/context.py\", line 281, in _Popen\n    return Popen(process_obj)\n", "  File \"/usr/local/lib/python3.10/multiprocessing/popen_fork.py\", line 19, in __init__\n    self._launch(process_obj)\n", "  File \"/usr/local/lib/python3.10/multiprocessing/popen_fork.py\", line 71, in _launch\n    code = process_obj._bootstrap(parent_sentinel=child_r)\n", "  File \"/usr/local/lib/python3.10/multiprocessing/process.py\", line 314, in _bootstrap\n    self.run()\n", "  File \"/usr/local/lib/python3.10/multiprocessing/process.py\", line 108, in run\n    self._target(*self._args, **self._kwargs)\n", "  File \"/usr/local/lib/python3.10/site-packages/mage_ai/orchestration/db/process.py\", line 15, in start_session_and_run\n    results = target(*args)\n", "  File \"/usr/local/lib/python3.10/site-packages/mage_ai/server/scheduler_manager.py\", line 50, in run_scheduler\n    LoopTimeTrigger().start()\n", "  File \"/usr/local/lib/python3.10/site-packages/mage_ai/orchestration/triggers/loop_time_trigger.py\", line 14, in start\n    self.run()\n", "  File \"/usr/local/lib/python3.10/site-packages/mage_ai/orchestration/triggers/time_trigger.py\", line 11, in run\n    schedule_all()\n", "  File \"/usr/local/lib/python3.10/site-packages/mage_ai/orchestration/pipeline_scheduler_original.py\", line 1610, in schedule_all\n    PipelineScheduler(r).schedule()\n", "  File \"/usr/local/lib/python3.10/site-packages/mage_ai/orchestration/db/__init__.py\", line 149, in func_with_rollback\n    return func(*args, **kwargs)\n", "  File \"/usr/local/lib/python3.10/site-packages/mage_ai/orchestration/pipeline_scheduler_original.py\", line 315, in schedule\n    self.__schedule_blocks(block_runs)\n", "  File \"/usr/local/lib/python3.10/site-packages/mage_ai/orchestration/pipeline_scheduler_original.py\", line 591, in __schedule_blocks\n    job_manager.add_job(\n", "  File \"/usr/local/lib/python3.10/site-packages/mage_ai/orchestration/job_manager.py\", line 27, in add_job\n    self.queue.enqueue(job_id, target, *args, **kwargs)\n", "  File \"/usr/local/lib/python3.10/site-packages/mage_ai/orchestration/queue/process_queue.py\", line 108, in enqueue\n    self.start_worker_pool()\n", "  File \"/usr/local/lib/python3.10/site-packages/mage_ai/orchestration/queue/process_queue.py\", line 183, in start_worker_pool\n    self.worker_pool_proc.start()\n", "  File \"/usr/local/lib/python3.10/multiprocessing/process.py\", line 121, in start\n    self._popen = self._Popen(self)\n", "  File \"/usr/local/lib/python3.10/multiprocessing/context.py\", line 224, in _Popen\n    return _default_context.get_context().Process._Popen(process_obj)\n", "  File \"/usr/local/lib/python3.10/multiprocessing/context.py\", line 281, in _Popen\n    return Popen(process_obj)\n", "  File \"/usr/local/lib/python3.10/multiprocessing/popen_fork.py\", line 19, in __init__\n    self._launch(process_obj)\n", "  File \"/usr/local/lib/python3.10/multiprocessing/popen_fork.py\", line 71, in _launch\n    code = process_obj._bootstrap(parent_sentinel=child_r)\n", "  File \"/usr/local/lib/python3.10/multiprocessing/process.py\", line 314, in _bootstrap\n    self.run()\n", "  File \"/usr/local/lib/python3.10/multiprocessing/process.py\", line 108, in run\n    self._target(*self._args, **self._kwargs)\n", "  File \"/usr/local/lib/python3.10/site-packages/mage_ai/orchestration/queue/process_queue.py\", line 288, in poll_job_and_execute\n    worker.start()\n", "  File \"/usr/local/lib/python3.10/multiprocessing/process.py\", line 121, in start\n    self._popen = self._Popen(self)\n", "  File \"/usr/local/lib/python3.10/multiprocessing/context.py\", line 224, in _Popen\n    return _default_context.get_context().Process._Popen(process_obj)\n", "  File \"/usr/local/lib/python3.10/multiprocessing/context.py\", line 281, in _Popen\n    return Popen(process_obj)\n", "  File \"/usr/local/lib/python3.10/multiprocessing/popen_fork.py\", line 19, in __init__\n    self._launch(process_obj)\n", "  File \"/usr/local/lib/python3.10/multiprocessing/popen_fork.py\", line 71, in _launch\n    code = process_obj._bootstrap(parent_sentinel=child_r)\n", "  File \"/usr/local/lib/python3.10/multiprocessing/process.py\", line 314, in _bootstrap\n    self.run()\n", "  File \"/usr/local/lib/python3.10/site-packages/newrelic/api/background_task.py\", line 117, in wrapper\n    return wrapped(*args, **kwargs)\n", "  File \"/usr/local/lib/python3.10/site-packages/mage_ai/orchestration/queue/process_queue.py\", line 253, in run\n    start_session_and_run(args[1], *args[2], **args[3])\n", "  File \"/usr/local/lib/python3.10/site-packages/mage_ai/orchestration/db/process.py\", line 15, in start_session_and_run\n    results = target(*args)\n", "  File \"/usr/local/lib/python3.10/site-packages/mage_ai/orchestration/pipeline_scheduler_original.py\", line 1135, in run_block\n    return ExecutorFactory.get_block_executor(\n", "  File \"/usr/local/lib/python3.10/site-packages/mage_ai/data_preparation/executors/block_executor.py\", line 641, in execute\n    on_failure(\n", "  File \"/usr/local/lib/python3.10/site-packages/mage_ai/orchestration/db/__init__.py\", line 149, in func_with_rollback\n    return func(*args, **kwargs)\n", "  File \"/usr/local/lib/python3.10/site-packages/mage_ai/orchestration/pipeline_scheduler_original.py\", line 422, in on_block_failure\n    self.logger.exception(\n", "  File \"/usr/local/lib/python3.10/site-packages/mage_ai/data_preparation/logging/logger.py\", line 30, in exception\n    self.__send_message('exception', message, **kwargs)\n", "  File \"/usr/local/lib/python3.10/site-packages/mage_ai/data_preparation/logging/logger.py\", line 59, in __send_message\n    data['error_stack'] = traceback.format_stack(),\n"]], "error_stacktrace": ["Command '['Rscript', '--vanilla', '/tmp/f16f2f8f-daeb-4838-b29b-2799532c782d.r']' returned non-zero exit status 1."]}
Traceback (most recent call last):
  File "/usr/local/lib/python3.10/site-packages/mage_ai/data_preparation/executors/block_executor.py", line 613, in execute
    result = __execute_with_retry()
  File "/usr/local/lib/python3.10/site-packages/mage_ai/shared/retry.py", line 54, in retry_func
    raise e
  File "/usr/local/lib/python3.10/site-packages/mage_ai/shared/retry.py", line 38, in retry_func
    return func(*args, **kwargs)
  File "/usr/local/lib/python3.10/site-packages/mage_ai/data_preparation/executors/block_executor.py", line 588, in __execute_with_retry
    return self._execute(
  File "/usr/local/lib/python3.10/site-packages/mage_ai/data_preparation/executors/block_executor.py", line 1077, in _execute
    result = self.block.execute_sync(
  File "/usr/local/lib/python3.10/site-packages/mage_ai/data_preparation/models/block/__init__.py", line 1315, in execute_sync
    raise err
  File "/usr/local/lib/python3.10/site-packages/mage_ai/data_preparation/models/block/__init__.py", line 1224, in execute_sync
    output = self.execute_block(
  File "/usr/local/lib/python3.10/site-packages/mage_ai/data_preparation/models/block/__init__.py", line 1530, in execute_block
    outputs = self._execute_block(
  File "/usr/local/lib/python3.10/site-packages/mage_ai/data_preparation/models/block/r/__init__.py", line 158, in _execute_block
    outputs = execute_r_code(
  File "/usr/local/lib/python3.10/site-packages/mage_ai/data_preparation/models/block/r/__init__.py", line 57, in execute_r_code
    __execute_r_code(file_path)
  File "/usr/local/lib/python3.10/site-packages/mage_ai/data_preparation/models/block/r/__init__.py", line 139, in __execute_r_code
    subprocess.run(
  File "/usr/local/lib/python3.10/subprocess.py", line 526, in run
    raise CalledProcessError(retcode, process.args,
subprocess.CalledProcessError: Command '['Rscript', '--vanilla', '/tmp/f16f2f8f-daeb-4838-b29b-2799532c782d.r']' returned non-zero exit status 1.
2024-04-18T20:46:44 {"cpu": 0.37255859375, "cpu_total": 2, "cpu_usage": 0.186279296875, "memory": 4635.0, "memory_total": 8883.0, "memory_usage": 0.5217831813576495, "pipeline_run_id": 3, "pipeline_schedule_id": 4, "pipeline_uuid": "playful_grimoire", "hostname": "7902c592f721", "level": "INFO", "message": "Pipeline playful_grimoire for run 3 in schedule 4 is alive.", "timestamp": 1713473204.936893, "uuid": "7a0a48deacc14ae28c71afce740fb4f7"}
